Workbook

Sheet Sheet1
A1: ID_CLIENTE | B1: FECHA_ALTA | C1: FECHA_VENTA | D1: DIAS_DESDE_ALTA | E1: SKU | F1: DESCRIPCION | G1: PIEZAS
A2: 1001423 | B2: 46024 | C2: 46028 | D2: 4 | E2: 2398 | F2: AEROSOL NEGRO MATE | G2: 6
A3: 1001423 | B3: 46024 | C3: 46031 | D3: 7 | E3: 2399 | F3: AEROSOL NEGRO BRILLANTE | G3: 12
A4: 1001423 | B4: 46024 | C4: 46041 | D4: 17 | E4: 2451 | F4: AEROSOL SUPER ORO | G4: 6
A5: 1001423 | B5: 46024 | C5: 46051 | D5: 27 | E5: 2300 | F5: AEROSOL BLANCO BRILLANTE | G5: 3
A6: 1001423 | B6: 46024 | C6: 46051 | D6: 27 | E6: 2301 | F6: AEROSOL BLANCO MATE | G6: 6
A7: 1001423 | B7: 46024 | C7: 46051 | D7: 27 | E7: 2343 | F7: AEROSOL ROSA | G7: 3
A8: 1001423 | B8: 46024 | C8: 46051 | D8: 27 | E8: 2344 | F8: AEROSOL MORADO | G8: 3
A9: 1001423 | B9: 46024 | C9: 46051 | D9: 27 | E9: 2345 | F9: AEROSOL ROJO | G9: 3
A10: 1001423 | B10: 46024 | C10: 46051 | D10: 27 | E10: 2390 | F10: AEROSOL ALUMINIO | G10: 3
A11: 1001423 | B11: 46024 | C11: 46051 | D11: 27 | E11: 2397 | F11: AEROSOL NEGRO SEMI BRILLANTE | G11: 3
A12: 1001423 | B12: 46024 | C12: 46051 | D12: 27 | E12: 2398 | F12: AEROSOL NEGRO MATE | G12: 6
A13: 1001423 | B13: 46024 | C13: 46051 | D13: 27 | E13: 2454 | F13: AEROSOL PRISA SUPER CROMO | G13: 3
... A1278: 1002656 | B1278: 46248 | C1278: 46258 | D1278: 10 | E1278: VG-50014 | F1278: VINILICA GLOSI BLANCO ULTRA | G1278: 6

Sheet Hoja1
A3: 1001423
A4: 1001441
A5: 1001446
A6: 1001448
A7: 1001456
A8: 1001467
A9: 1001492
A10: 1001512
A11: 1001514
A12: 1001515
A13: 1001521
A14: 1001564
... A133: 1002656

Sheet TD
A3: Promedio de PIEZAS | B3: ID_CLIENTE
A4: SKU | B4: 1001423 | C4: 1001441 | D4: 1001446 | E4: 1001448 | F4: 1001456 | G4: 1001467 | H4: 1001492 | I4: 1001512 | J4: 1001514 | K4: 1001515 | L4: 1001521 | M4: 1001564 | N4: 1001569 | O4: 1001574 | P4: 1001578 | Q4: 1001582 | R4: 1001588 | S4: 1001594 | T4: 1001595 | U4: 1001599 | V4: 1001600 | W4: 1001608 | X4: 1001609 | Y4: 1001611 | Z4: 1001615 | AA4: 1001626 | AB4: 1001630 | AC4: 1001631 | AD4: 1001637 | AE4: 1001640 | AF4: 1001641 | AG4: 1001648 | AH4: 1001649 | AI4: 1001696 | AJ4: 1001703 | AK4: 1001706 | AL4: 1001709 | AM4: 1001714 | AN4: 1001717 | AO4: 1001720 | AP4: 1001734 | AQ4: 1001742 | AR4: 1001765 | AS4: 1001767 | AT4: 1001772 | AU4: 1001784 | AV4: 1001792 | AW4: 1001793 | AX4: 1001804 | AY4: 1001808 | AZ4: 1001818 | BA4: 1001843 | BB4: 1001844 | BC4: 1001848 | BD4: 1001849 | BE4: 1001852 | BF4: 1001858 | BG4: 1001859 | BH4: 1001871 | BI4: 1001883 | BJ4: 1001884 | BK4: 1001896 | BL4: 1001900 | BM4: 1001914 | BN4: 1001919 | BO4: 1001949 | BP4: 1001981 | BQ4: 1001983 | BR4: 1001999 | BS4: 1002001 | BT4: 1002005 | BU4: 1002010 | BV4: 1002048 | BW4: 1002058 | BX4: 1002063 | BY4: 1002093 | BZ4: 1002094 | CA4: 1002103 | CB4: 1002105 | CC4: 1002109 | CD4: 1002125 | CE4: 1002129 | CF4: 1002134 | CG4: 1002136 | CH4: 1002146 | CI4: 1002148 | CJ4: 1002150 | CK4: 1002154 | CL4: 1002159 | CM4: 1002161 | CN4: 1002162 | CO4: 1002170 | CP4: 1002189 | CQ4: 1002196 | CR4: 1002201 | CS4: 1002208 | CT4: 1002209 | CU4: 1002232 | CV4: 1002239 | CW4: 1002241 | CX4: 1002246 | CY4: 1002262 | CZ4: 1002283 | DA4: 1002309 | DB4: 1002321 | DC4: 1002348 | DD4: 1002356 | DE4: 1002372 | DF4: 1002385 | DG4: 1002399 | DH4: 1002400 | DI4: 1002421 | DJ4: 1002422 | DK4: 1002425 | DL4: 1002433 | DM4: 1002441 | DN4: 1002459 | DO4: 1002502 | DP4: 1002514 | DQ4: 1002521 | DR4: 1002542 | DS4: 1002549 | DT4: 1002551 | DU4: 1002559 | DV4: 1002562 | DW4: 1002575 | DX4: 1002581 | DY4: 1002583 | DZ4: 1002617 | EA4: 1002644 | EB4: 1002656 | EC4: Total general
A5: 360-N | P5: 100 | EC5: 100
A6: 9185 | AV6: 100 | EC6: 100
A7: 9184 | AV7: 50 | EC7: 50
A8: 38551 | BO8: 18 | EC8: 18
A9: SRG-10453 | AV9: 16 | EC9: 16
A10: 21986 | DT10: 12 | EC10: 12
A11: 2367 | DH11: 12 | EC11: 12
A12: 28266 | BR12: 12 | EC12: 12
A13: 22006 | BO13: 12 | EC13: 12
A14: 28136 | BR14: 12 | EC14: 12
A15: 28356 | BR15: 12 | EC15: 12
A16: 28646 | F16: 6 | BR16: 24 | DG16: 6 | DL16: 6 | EC16: 10.5
A17: 29004 | F17: 6 | M17: 12 | EC17: 9
A18: 28656 | BR18: 12 | CZ18: 6 | EC18: 9
A19: 22005 | BO19: 6 | DT19: 12 | EC19: 9
A20: 28936 | BJ20: 6 | BR20: 12 | DG20: 6 | EC20: 8
A21: SRG-10996 | U21: 6 | BC21: 12 | BQ21: 6 | CG21: 6 | EC21: 7.5
A22: SRG-10006 | BC22: 12 | BQ22: 6 | CG22: 6 | DX22: 6 | EC22: 7.5
A23: IG-40561 | AM23: 1 | BB23: 3 | BP23: 6 | BV23: 26 | DB23: 1 | EC23: 7.4
A24: IG-50001 | S24: 1 | AG24: 6 | BD24: 1 | BE24: 6 | BP24: 6 | CB24: 19 | CG24: 2 | DB24: 3 | DC24: 3 | EC24: 7
A25: 2300 | B25: 3 | E25: 6 | K25: 6 | L25: 7 | Q25: 12 | X25: 12 | Y25: 6 | AD25: 6 | AH25: 6 | AI25: 0 | AT25: 6 | AX25: 6 | BJ25: 6 | BO25: 24 | BP25: 12 | BQ25: 6 | BX25: 2 | CR25: 12 | CX25: 12 | DC25: 6 | DN25: 6 | DS25: 4.5 | DU25: 2 | EB25: 6 | EC25: 6.8846154
A26: 29012 | I26: 2 | AQ26: 2 | AU26: 2 | AV26: 40 | DI26: 3 | EC26: 6.4444444
A27: 2399 | B27: 12 | E27: 2 | G27: 6 | K27: 6 | X27: 12 | Y27: 6 | AD27: 2 | AH27: 6 | AI27: 0 | AL27: 12 | AT27: 6 | AX27: 6 | BA27: 12 | BJ27: 6 | BK27: 3 | BL27: 1 | CR27: 6 | CX27: 12 | DC27: 6 | DH27: 24 | DN27: 12 | DS27: 6 | DU27: 2 | EB27: 6 | EC27: 6.2
A28: 2380 | AT28: 6 | BA28: 6 | CX28: 6 | EC28: 6
A29: 28774 | AC29: 6 | BP29: 6 | EC29: 6
A30: 38061 | BO30: 6 | EC30: 6
A31: 15934 | AS31: 6 | EC31: 6
A32: 28106 | DG32: 6 | DL32: 6 | EC32: 6
A33: 28864 | DT33: 6 | EC33: 6
A34: 15994 | DV34: 6 | EC34: 6
A35: 33014 | DT35: 6 | EC35: 6
A36: 28154 | Z36: 6 | EC36: 6
A37: 22004 | DT37: 6 | EC37: 6
A38: 21584 | BO38: 6 | EC38: 6
A39: 28756 | DG39: 6 | EC39: 6
A40: 2375 | BO40: 6 | EC40: 6
A41: 28775 | BP41: 6 | EC41: 6
A42: SRG-11004 | BC42: 6 | EC42: 6
...

Sheet POR PRODUCTO MAS COM
A1: PEDIDO SUGERIDO CLIENTES NUEVOS FELIPE PAIZ
A3: Cuenta de PIEZAS | D3: =SUM(D5:D24) -> 6064.64 | E3: =SUM(E5:E24) -> 4776.74 | H3: PRECIOS | L3: =SUM(L5:L27) -> 58 | M3: =SUM(M5:M27) -> 6872.37 | N3: =SUM(N5:N27) -> 5150.07
A4: SKU | B4: PRODUCTO | C4: CUANTOS CLIENTES COMPRARON POR PRIMERA VEZ / 149 CLIENTES NUEVOS | D4: TY | E4: TQ | F4: UNIDADES PROMEDIO DE COMPRA | G4: ENTERO | H4: TY | I4: TQ | K4: MARCA | L4: PROPUESTA | M4: TY | N4: TQ | O4: VECES QUE SE HIZO RECOMPRA (ENTRE 1RA COMP <90 DIAS) | P4: # CLIENTES QUE HICIERON LA RECOMPRA / 149 ALTAS / 131 HICIERON COMPRA EN <30 DÍAS DE SU ALTA | Q4: RKNG # CLIENTE | R4: % REC | S4: PIEZAS COMPRADAS | T4: # CLIENTES QUE HICIERON LA RECOMPRA / 149 ALTAS / 131 HICIERON COMPRA EN <30 DÍAS DE SU ALTA | U4: RKNG # CLIENTE
A5: IG-30001 | B5: =_xlfn.XLOOKUP(A:A,[1]Hoja1!$C:$C,[1]Hoja1!$D:$D,"",0,1) -> IMPERGLOSI AGUACERO BLANCO 3A | C5: 61 | D5: =_xlfn.XLOOKUP(A:A,[2]Hoja1!$C:$C,[2]Hoja1!$H:$H,"",0,1) -> 885.34 | E5: =_xlfn.XLOOKUP(A:A,[1]Hoja1!$C:$C,[1]Hoja1!$H:$H,"",0,1) -> 708.62 | F5: =_xlfn.XLOOKUP(A:A,TD!A:A,TD!EC:EC,"",0,1) -> 3.4590164 | G5: =INT(F5) -> 3 | H5: =D5*$G$5 -> 2656.02 | I5: =E5*$G$5 -> 2125.86 | J5: IG-30001 | K5: =_xlfn.XLOOKUP(J:J,'[3]FILTROS 2'!$A:$A,'[3]FILTROS 2'!$E:$E,"",0,1) -> IMPERGLOSI AGUACERO 3 AÑOS | M5: =$L$5*D5 -> 0 | N5: =$L5*E5 -> 0 | O5: =_xlfn.XLOOKUP(A:A,[4]TD90D!$A:$A,[4]TD90D!$CW:$CW,"",0,1) -> 65 | P5: =_xlfn.XLOOKUP(A:A,[4]TD90D!$A:$A,[4]TD90D!$CX:$CX,"",0,1) -> 25 | Q5: =_xlfn.XLOOKUP(A:A,[4]TD90D!$A:$A,[4]TD90D!$DA:$DA,"",0,1) -> 2 | R5: =P5/C5 -> 0.40983607 | S5: =_xlfn.XLOOKUP(A:A,'[4]TD90D PZAS'!$A:$A,'[4]TD90D PZAS'!$CW:$CW,"",0,1) -> 244 | T5: =_xlfn.XLOOKUP(A:A,'[4]TD90D PZAS'!$A:$A,'[4]TD90D PZAS'!$CX:$CX,"",0,1) -> 23 | U5: =_xlfn.XLOOKUP(A:A,'[4]TD90D PZAS'!$A:$A,'[4]TD90D PZAS'!$DA:$DA,"",0,1) -> 2
A6: IG-30561 | B6: =_xlfn.XLOOKUP(A:A,[1]Hoja1!$C:$C,[1]Hoja1!$D:$D,"",0,1) -> IMPERGLOSI AGUACERO TERRACOTA 3A | C6: 52 | D6: =_xlfn.XLOOKUP(A:A,[2]Hoja1!$C:$C,[2]Hoja1!$H:$H,"",0,1) -> 885.34 | E6: =_xlfn.XLOOKUP(A:A,[1]Hoja1!$C:$C,[1]Hoja1!$H:$H,"",0,1) -> 708.62 | F6: =_xlfn.XLOOKUP(A:A,TD!A:A,TD!EC:EC,"",0,1) -> 4.0769231 | G6: =INT(F6) -> 4 | H6: =D6*$G$5 -> 2656.02 | I6: =E6*$G$5 -> 2125.86 | J6: IG-30561 | K6: =_xlfn.XLOOKUP(J:J,'[3]FILTROS 2'!$A:$A,'[3]FILTROS 2'!$E:$E,"",0,1) -> IMPERGLOSI AGUACERO 3 AÑOS | M6: =L6*D6 -> 0 | N6: =$L6*E6 -> 0 | O6: =_xlfn.XLOOKUP(A:A,[4]TD90D!$A:$A,[4]TD90D!$CW:$CW,"",0,1) -> 81 | P6: =_xlfn.XLOOKUP(A:A,[4]TD90D!$A:$A,[4]TD90D!$CX:$CX,"",0,1) -> 25 | Q6: =_xlfn.XLOOKUP(A:A,[4]TD90D!$A:$A,[4]TD90D!$DA:$DA,"",0,1) -> 1 | R6: =P6/C6 -> 0.48076923 | S6: =_xlfn.XLOOKUP(A:A,'[4]TD90D PZAS'!$A:$A,'[4]TD90D PZAS'!$CW:$CW,"",0,1) -> 353 | T6: =_xlfn.XLOOKUP(A:A,'[4]TD90D PZAS'!$A:$A,'[4]TD90D PZAS'!$CX:$CX,"",0,1) -> 23 | U6: =_xlfn.XLOOKUP(A:A,'[4]TD90D PZAS'!$A:$A,'[4]TD90D PZAS'!$DA:$DA,"",0,1) -> 1
A7: 28984 | B7: =_xlfn.XLOOKUP(A:A,[1]Hoja1!$C:$C,[1]Hoja1!$D:$D,"",0,1) -> BRILLON NEGRO | C7: 52 | D7: =_xlfn.XLOOKUP(A:A,[2]Hoja1!$C:$C,[2]Hoja1!$H:$H,"",0,1) -> 150.86 | E7: =_xlfn.XLOOKUP(A:A,[1]Hoja1!$C:$C,[1]Hoja1!$H:$H,"",0,1) -> 112.93 | F7: =_xlfn.XLOOKUP(A:A,TD!A:A,TD!EC:EC,"",0,1) -> 3.9423077 | G7: =INT(F7) -> 3 | H7: =D7*$G$5 -> 452.58 | I7: =E7*$G$5 -> 338.79 | J7: 28984 | K7: =_xlfn.XLOOKUP(J:J,'[3]FILTROS 2'!$A:$A,'[3]FILTROS 2'!$E:$E,"",0,1) -> ESMALTE - BRILLON | L7: 4 | M7: =L7*D7 -> 603.44 | N7: =$L7*E7 -> 451.72 | O7: =_xlfn.XLOOKUP(A:A,[4]TD90D!$A:$A,[4]TD90D!$CW:$CW,"",0,1) -> 58 | P7: =_xlfn.XLOOKUP(A:A,[4]TD90D!$A:$A,[4]TD90D!$CX:$CX,"",0,1) -> 22 | Q7: =_xlfn.XLOOKUP(A:A,[4]TD90D!$A:$A,[4]TD90D!$DA:$DA,"",0,1) -> 3 | R7: =P7/C7 -> 0.42307692 | S7: =_xlfn.XLOOKUP(A:A,'[4]TD90D PZAS'!$A:$A,'[4]TD90D PZAS'!$CW:$CW,"",0,1) -> 293 | T7: =_xlfn.XLOOKUP(A:A,'[4]TD90D PZAS'!$A:$A,'[4]TD90D PZAS'!$CX:$CX,"",0,1) -> 21 | U7: =_xlfn.XLOOKUP(A:A,'[4]TD90D PZAS'!$A:$A,'[4]TD90D PZAS'!$DA:$DA,"",0,1) -> 3
A8: 28004 | B8: =_xlfn.XLOOKUP(A:A,[1]Hoja1!$C:$C,[1]Hoja1!$D:$D,"",0,1) -> ESMALTE BRILLON BLANCO | C8: 48 | D8: =_xlfn.XLOOKUP(A:A,[2]Hoja1!$C:$C,[2]Hoja1!$H:$H,"",0,1) -> 150.86 | E8: =_xlfn.XLOOKUP(A:A,[1]Hoja1!$C:$C,[1]Hoja1!$H:$H,"",0,1) -> 112.93 | F8: =_xlfn.XLOOKUP(A:A,TD!A:A,TD!EC:EC,"",0,1) -> 4.1666667 | G8: =INT(F8) -> 4 | H8: =D8*$G$5 -> 452.58 | I8: =E8*$G$5 -> 338.79 | J8: 28004 | K8: =_xlfn.XLOOKUP(J:J,'[3]FILTROS 2'!$A:$A,'[3]FILTROS 2'!$E:$E,"",0,1) -> ESMALTE - BRILLON | L8: 4 | M8: =L8*D8 -> 603.44 | N8: =$L8*E8 -> 451.72 | O8: =_xlfn.XLOOKUP(A:A,[4]TD90D!$A:$A,[4]TD90D!$CW:$CW,"",0,1) -> 57 | P8: =_xlfn.XLOOKUP(A:A,[4]TD90D!$A:$A,[4]TD90D!$CX:$CX,"",0,1) -> 21 | Q8: =_xlfn.XLOOKUP(A:A,[4]TD90D!$A:$A,[4]TD90D!$DA:$DA,"",0,1) -> 4 | R8: =P8/C8 -> 0.4375 | S8: =_xlfn.XLOOKUP(A:A,'[4]TD90D PZAS'!$A:$A,'[4]TD90D PZAS'!$CW:$CW,"",0,1) -> 308 | T8: =_xlfn.XLOOKUP(A:A,'[4]TD90D PZAS'!$A:$A,'[4]TD90D PZAS'!$CX:$CX,"",0,1) -> 20 | U8: =_xlfn.XLOOKUP(A:A,'[4]TD90D PZAS'!$A:$A,'[4]TD90D PZAS'!$DA:$DA,"",0,1) -> 4
A9: 28005 | B9: =_xlfn.XLOOKUP(A:A,[1]Hoja1!$C:$C,[1]Hoja1!$D:$D,"",0,1) -> BRILLON BLANCO | C9: 46 | D9: =_xlfn.XLOOKUP(A:A,[2]Hoja1!$C:$C,[2]Hoja1!$H:$H,"",0,1) -> 90.52 | E9: =_xlfn.XLOOKUP(A:A,[1]Hoja1!$C:$C,[1]Hoja1!$H:$H,"",0,1) -> 67.24 | F9: =_xlfn.XLOOKUP(A:A,TD!A:A,TD!EC:EC,"",0,1) -> 3.6956522 | G9: =INT(F9) -> 3 | H9: =D9*$G$5 -> 271.56 | I9: =E9*$G$5 -> 201.72 | J9: 28005 | K9: =_xlfn.XLOOKUP(J:J,'[3]FILTROS 2'!$A:$A,'[3]FILTROS 2'!$E:$E,"",0,1) -> ESMALTE - BRILLON | L9: 3 | M9: =L9*D9 -> 271.56 | N9: =$L9*E9 -> 201.72 | O9: =_xlfn.XLOOKUP(A:A,[4]TD90D!$A:$A,[4]TD90D!$CW:$CW,"",0,1) -> 46 | P9: =_xlfn.XLOOKUP(A:A,[4]TD90D!$A:$A,[4]TD90D!$CX:$CX,"",0,1) -> 16 | Q9: =_xlfn.XLOOKUP(A:A,[4]TD90D!$A:$A,[4]TD90D!$DA:$DA,"",0,1) -> 5 | R9: =P9/C9 -> 0.34782609 | S9: =_xlfn.XLOOKUP(A:A,'[4]TD90D PZAS'!$A:$A,'[4]TD90D PZAS'!$CW:$CW,"",0,1) -> 211 | T9: =_xlfn.XLOOKUP(A:A,'[4]TD90D PZAS'!$A:$A,'[4]TD90D PZAS'!$CX:$CX,"",0,1) -> 15 | U9: =_xlfn.XLOOKUP(A:A,'[4]TD90D PZAS'!$A:$A,'[4]TD90D PZAS'!$DA:$DA,"",0,1) -> 6
A10: 28985 | B10: =_xlfn.XLOOKUP(A:A,[1]Hoja1!$C:$C,[1]Hoja1!$D:$D,"",0,1) -> BRILLON NEGRO | C10: 36 | D10: =_xlfn.XLOOKUP(A:A,[2]Hoja1!$C:$C,[2]Hoja1!$H:$H,"",0,1) -> 90.52 | E10: =_xlfn.XLOOKUP(A:A,[1]Hoja1!$C:$C,[1]Hoja1!$H:$H,"",0,1) -> 67.24 | F10: =_xlfn.XLOOKUP(A:A,TD!A:A,TD!EC:EC,"",0,1) -> 4.1944444 | G10: =INT(F10) -> 4 | H10: =D10*$G$5 -> 271.56 | I10: =E10*$G$5 -> 201.72 | J10: 28985 | K10: =_xlfn.XLOOKUP(J:J,'[3]FILTROS 2'!$A:$A,'[3]FILTROS 2'!$E:$E,"",0,1) -> ESMALTE - BRILLON | L10: 4 | M10: =L10*D10 -> 362.08 | N10: =$L10*E10 -> 268.96 | O10: =_xlfn.XLOOKUP(A:A,[4]TD90D!$A:$A,[4]TD90D!$CW:$CW,"",0,1) -> 28 | P10: =_xlfn.XLOOKUP(A:A,[4]TD90D!$A:$A,[4]TD90D!$CX:$CX,"",0,1) -> 12 | Q10: =_xlfn.XLOOKUP(A:A,[4]TD90D!$A:$A,[4]TD90D!$DA:$DA,"",0,1) -> 8 | R10: =P10/C10 -> 0.33333333 | S10: =_xlfn.XLOOKUP(A:A,'[4]TD90D PZAS'!$A:$A,'[4]TD90D PZAS'!$CW:$CW,"",0,1) -> 105 | T10: =_xlfn.XLOOKUP(A:A,'[4]TD90D PZAS'!$A:$A,'[4]TD90D PZAS'!$CX:$CX,"",0,1) -> 11 | U10: =_xlfn.XLOOKUP(A:A,'[4]TD90D PZAS'!$A:$A,'[4]TD90D PZAS'!$DA:$DA,"",0,1) -> 11
A11: 28986 | B11: =_xlfn.XLOOKUP(A:A,[1]Hoja1!$C:$C,[1]Hoja1!$D:$D,"",0,1) -> BRILLON NEGRO | C11: 32 | D11: =_xlfn.XLOOKUP(A:A,[2]Hoja1!$C:$C,[2]Hoja1!$H:$H,"",0,1) -> 58.62 | E11: =_xlfn.XLOOKUP(A:A,[1]Hoja1!$C:$C,[1]Hoja1!$H:$H,"",0,1) -> 43.97 | F11: =_xlfn.XLOOKUP(A:A,TD!A:A,TD!EC:EC,"",0,1) -> 5.21875 | G11: =INT(F11) -> 5 | H11: =D11*$G$5 -> 175.86 | I11: =E11*$G$5 -> 131.91 | J11: 28986 | K11: =_xlfn.XLOOKUP(J:J,'[3]FILTROS 2'!$A:$A,'[3]FILTROS 2'!$E:$E,"",0,1) -> ESMALTE - BRILLON | L11: 4 | M11: =L11*D11 -> 234.48 | N11: =$L11*E11 -> 175.88 | O11: =_xlfn.XLOOKUP(A:A,[4]TD90D!$A:$A,[4]TD90D!$CW:$CW,"",0,1) -> 29 | P11: =_xlfn.XLOOKUP(A:A,[4]TD90D!$A:$A,[4]TD90D!$CX:$CX,"",0,1) -> 11 | Q11: =_xlfn.XLOOKUP(A:A,[4]TD90D!$A:$A,[4]TD90D!$DA:$DA,"",0,1) -> 10 | R11: =P11/C11 -> 0.34375 | S11: =_xlfn.XLOOKUP(A:A,'[4]TD90D PZAS'!$A:$A,'[4]TD90D PZAS'!$CW:$CW,"",0,1) -> 154 | T11: =_xlfn.XLOOKUP(A:A,'[4]TD90D PZAS'!$A:$A,'[4]TD90D PZAS'!$CX:$CX,"",0,1) -> 11 | U11: =_xlfn.XLOOKUP(A:A,'[4]TD90D PZAS'!$A:$A,'[4]TD90D PZAS'!$DA:$DA,"",0,1) -> 8
A12: 28006 | B12: =_xlfn.XLOOKUP(A:A,[1]Hoja1!$C:$C,[1]Hoja1!$D:$D,"",0,1) -> BRILLON BLANCO | C12: 32 | D12: =_xlfn.XLOOKUP(A:A,[2]Hoja1!$C:$C,[2]Hoja1!$H:$H,"",0,1) -> 58.62 | E12: =_xlfn.XLOOKUP(A:A,[1]Hoja1!$C:$C,[1]Hoja1!$H:$H,"",0,1) -> 43.97 | F12: =_xlfn.XLOOKUP(A:A,TD!A:A,TD!EC:EC,"",0,1) -> 5.21875 | G12: =INT(F12) -> 5 | H12: =D12*$G$5 -> 175.86 | I12: =E12*$G$5 -> 131.91 | J12: 28006 | K12: =_xlfn.XLOOKUP(J:J,'[3]FILTROS 2'!$A:$A,'[3]FILTROS 2'!$E:$E,"",0,1) -> ESMALTE - BRILLON | L12: 4 | M12: =L12*D12 -> 234.48 | N12: =$L12*E12 -> 175.88 | O12: =_xlfn.XLOOKUP(A:A,[4]TD90D!$A:$A,[4]TD90D!$CW:$CW,"",0,1) -> 26 | P12: =_xlfn.XLOOKUP(A:A,[4]TD90D!$A:$A,[4]TD90D!$CX:$CX,"",0,1) -> 11 | Q12: =_xlfn.XLOOKUP(A:A,[4]TD90D!$A:$A,[4]TD90D!$DA:$DA,"",0,1) -> 12 | R12: =P12/C12 -> 0.34375 | S12: =_xlfn.XLOOKUP(A:A,'[4]TD90D PZAS'!$A:$A,'[4]TD90D PZAS'!$CW:$CW,"",0,1) -> 130 | T12: =_xlfn.XLOOKUP(A:A,'[4]TD90D PZAS'!$A:$A,'[4]TD90D PZAS'!$CX:$CX,"",0,1) -> 11 | U12: =_xlfn.XLOOKUP(A:A,'[4]TD90D PZAS'!$A:$A,'[4]TD90D PZAS'!$DA:$DA,"",0,1) -> 10
A13: 2399 | B13: =_xlfn.XLOOKUP(A:A,[1]Hoja1!$C:$C,[1]Hoja1!$D:$D,"",0,1) -> AEROSOL NEGRO BRILLANTE | C13: 30 | D13: =_xlfn.XLOOKUP(A:A,[2]Hoja1!$C:$C,[2]Hoja1!$H:$H,"",0,1) -> 55.17 | E13: =_xlfn.XLOOKUP(A:A,[1]Hoja1!$C:$C,[1]Hoja1!$H:$H,"",0,1) -> 41.38 | F13: =_xlfn.XLOOKUP(A:A,TD!A:A,TD!EC:EC,"",0,1) -> 6.2 | G13: =INT(F13) -> 6 | H13: =D13*$G$5 -> 165.51 | I13: =E13*$G$5 -> 124.14 | J13: 2399 | K13: =_xlfn.XLOOKUP(J:J,'[3]FILTROS 2'!$A:$A,'[3]FILTROS 2'!$E:$E,"",0,1) -> AEROSOLES PRISA | L13: 6 | M13: =L13*D13 -> 331.02 | N13: =$L13*E13 -> 248.28 | O13: =_xlfn.XLOOKUP(A:A,[4]TD90D!$A:$A,[4]TD90D!$CW:$CW,"",0,1) -> 44 | P13: =_xlfn.XLOOKUP(A:A,[4]TD90D!$A:$A,[4]TD90D!$CX:$CX,"",0,1) -> 16 | Q13: =_xlfn.XLOOKUP(A:A,[4]TD90D!$A:$A,[4]TD90D!$DA:$DA,"",0,1) -> 6 | R13: =P13/C13 -> 0.53333333 | S13: =_xlfn.XLOOKUP(A:A,'[4]TD90D PZAS'!$A:$A,'[4]TD90D PZAS'!$CW:$CW,"",0,1) -> 502 | T13: =_xlfn.XLOOKUP(A:A,'[4]TD90D PZAS'!$A:$A,'[4]TD90D PZAS'!$CX:$CX,"",0,1) -> 15 | U13: =_xlfn.XLOOKUP(A:A,'[4]TD90D PZAS'!$A:$A,'[4]TD90D PZAS'!$DA:$DA,"",0,1) -> 5
A14: 2300 | B14: =_xlfn.XLOOKUP(A:A,[1]Hoja1!$C:$C,[1]Hoja1!$D:$D,"",0,1) -> AEROSOL BLANCO BRILLANTE | C14: 26 | D14: =_xlfn.XLOOKUP(A:A,[2]Hoja1!$C:$C,[2]Hoja1!$H:$H,"",0,1) -> 55.17 | E14: =_xlfn.XLOOKUP(A:A,[1]Hoja1!$C:$C,[1]Hoja1!$H:$H,"",0,1) -> 41.38 | F14: =_xlfn.XLOOKUP(A:A,TD!A:A,TD!EC:EC,"",0,1) -> 6.8846154 | G14: =INT(F14) -> 6 | H14: =D14*$G$5 -> 165.51 | I14: =E14*$G$5 -> 124.14 | J14: 2300 | K14: =_xlfn.XLOOKUP(J:J,'[3]FILTROS 2'!$A:$A,'[3]FILTROS 2'!$E:$E,"",0,1) -> AEROSOLES PRISA | L14: 6 | M14: =L14*D14 -> 331.02 | N14: =$L14*E14 -> 248.28 | O14: =_xlfn.XLOOKUP(A:A,[4]TD90D!$A:$A,[4]TD90D!$CW:$CW,"",0,1) -> 30 | P14: =_xlfn.XLOOKUP(A:A,[4]TD90D!$A:$A,[4]TD90D!$CX:$CX,"",0,1) -> 13 | Q14: =_xlfn.XLOOKUP(A:A,[4]TD90D!$A:$A,[4]TD90D!$DA:$DA,"",0,1) -> 7 | R14: =P14/C14 -> 0.5 | S14: =_xlfn.XLOOKUP(A:A,'[4]TD90D PZAS'!$A:$A,'[4]TD90D PZAS'!$CW:$CW,"",0,1) -> 229 | T14: =_xlfn.XLOOKUP(A:A,'[4]TD90D PZAS'!$A:$A,'[4]TD90D PZAS'!$CX:$CX,"",0,1) -> 13 | U14: =_xlfn.XLOOKUP(A:A,'[4]TD90D PZAS'!$A:$A,'[4]TD90D PZAS'!$DA:$DA,"",0,1) -> 7
A15: 29014 | B15: =_xlfn.XLOOKUP(A:A,[1]Hoja1!$C:$C,[1]Hoja1!$D:$D,"",0,1) -> RELLENADOR AUTOMOTRIZ C/CATAL. ROJO | C15: 25 | D15: =_xlfn.XLOOKUP(A:A,[2]Hoja1!$C:$C,[2]Hoja1!$H:$H,"",0,1) -> 137.07 | E15: =_xlfn.XLOOKUP(A:A,[1]Hoja1!$C:$C,[1]Hoja1!$H:$H,"",0,1) -> 103.45 | F15: =_xlfn.XLOOKUP(A:A,TD!A:A,TD!EC:EC,"",0,1) -> 5.16 | G15: =INT(F15) -> 5 | H15: =D15*$G$5 -> 411.21 | I15: =E15*$G$5 -> 310.35 | J15: 29014 | K15: =_xlfn.XLOOKUP(J:J,'[3]FILTROS 2'!$A:$A,'[3]FILTROS 2'!$E:$E,"",0,1) -> PASTA RELLENADORA | L15: 3 | M15: =L15*D15 -> 411.21 | N15: =$L15*E15 -> 310.35 | O15: =_xlfn.XLOOKUP(A:A,[4]TD90D!$A:$A,[4]TD90D!$CW:$CW,"",0,1) -> 27 | P15: =_xlfn.XLOOKUP(A:A,[4]TD90D!$A:$A,[4]TD90D!$CX:$CX,"",0,1) -> 11 | Q15: =_xlfn.XLOOKUP(A:A,[4]TD90D!$A:$A,[4]TD90D!$DA:$DA,"",0,1) -> 11 | R15: =P15/C15 -> 0.44 | S15: =_xlfn.XLOOKUP(A:A,'[4]TD90D PZAS'!$A:$A,'[4]TD90D PZAS'!$CW:$CW,"",0,1) -> 140 | T15: =_xlfn.XLOOKUP(A:A,'[4]TD90D PZAS'!$A:$A,'[4]TD90D PZAS'!$CX:$CX,"",0,1) -> 11 | U15: =_xlfn.XLOOKUP(A:A,'[4]TD90D PZAS'!$A:$A,'[4]TD90D PZAS'!$DA:$DA,"",0,1) -> 9
A16: 79234 | B16: =_xlfn.XLOOKUP(A:A,[1]Hoja1!$C:$C,[1]Hoja1!$D:$D,"",0,1) -> SIAMIL ECONOMICO MI FL 20 KG | C16: 22 | D16: =_xlfn.XLOOKUP(A:A,[2]Hoja1!$C:$C,[2]Hoja1!$H:$H,"",0,1) -> 163.79 | E16: =_xlfn.XLOOKUP(A:A,[1]Hoja1!$C:$C,[1]Hoja1!$H:$H,"",0,1) -> 123.28 | F16: =_xlfn.XLOOKUP(A:A,TD!A:A,TD!EC:EC,"",0,1) -> 4.7727273 | G16: =INT(F16) -> 4 | H16: =D16*$G$5 -> 491.37 | I16: =E16*$G$5 -> 369.84 | J16: 79234 | K16: =_xlfn.XLOOKUP(J:J,'[3]FILTROS 2'!$A:$A,'[3]FILTROS 2'!$E:$E,"",0,1) -> SIAMIL | L16: 4 | M16: =L16*D16 -> 655.16 | N16: =$L16*E16 -> 493.12 | O16: =_xlfn.XLOOKUP(A:A,[4]TD90D!$A:$A,[4]TD90D!$CW:$CW,"",0,1) -> 31 | P16: =_xlfn.XLOOKUP(A:A,[4]TD90D!$A:$A,[4]TD90D!$CX:$CX,"",0,1) -> 11 | Q16: =_xlfn.XLOOKUP(A:A,[4]TD90D!$A:$A,[4]TD90D!$DA:$DA,"",0,1) -> 9 | R16: =P16/C16 -> 0.5 | S16: =_xlfn.XLOOKUP(A:A,'[4]TD90D PZAS'!$A:$A,'[4]TD90D PZAS'!$CW:$CW,"",0,1) -> 211 | T16: =_xlfn.XLOOKUP(A:A,'[4]TD90D PZAS'!$A:$A,'[4]TD90D PZAS'!$CX:$CX,"",0,1) -> 10 | U16: =_xlfn.XLOOKUP(A:A,'[4]TD90D PZAS'!$A:$A,'[4]TD90D PZAS'!$DA:$DA,"",0,1) -> 12
A17: IG-50561 | B17: =_xlfn.XLOOKUP(A:A,[1]Hoja1!$C:$C,[1]Hoja1!$D:$D,"",0,1) -> IMPERGLOSI AGUACERO TERRACOTA 5A | C17: 18 | D17: =_xlfn.XLOOKUP(A:A,[2]Hoja1!$C:$C,[2]Hoja1!$H:$H,"",0,1) -> 1118.97 | E17: =_xlfn.XLOOKUP(A:A,[1]Hoja1!$C:$C,[1]Hoja1!$H:$H,"",0,1) -> 896.55 | F17: =_xlfn.XLOOKUP(A:A,TD!A:A,TD!EC:EC,"",0,1) -> 3.6111111 | G17: =INT(F17) -> 3 | H17: =D17*$G$5 -> 3356.91 | I17: =E17*$G$5 -> 2689.65 | J17: IG-50561 | K17: =_xlfn.XLOOKUP(J:J,'[3]FILTROS 2'!$A:$A,'[3]FILTROS 2'!$E:$E,"",0,1) -> IMPERGLOSI AGUACERO 5 AÑOS | M17: =L17*D17 -> 0 | N17: =$L17*E17 -> 0 | O17: =_xlfn.XLOOKUP(A:A,[4]TD90D!$A:$A,[4]TD90D!$CW:$CW,"",0,1) -> 20 | P17: =_xlfn.XLOOKUP(A:A,[4]TD90D!$A:$A,[4]TD90D!$CX:$CX,"",0,1) -> 7 | Q17: =_xlfn.XLOOKUP(A:A,[4]TD90D!$A:$A,[4]TD90D!$DA:$DA,"",0,1) -> 0 | R17: =P17/C17 -> 0.38888889 | S17: =_xlfn.XLOOKUP(A:A,'[4]TD90D PZAS'!$A:$A,'[4]TD90D PZAS'!$CW:$CW,"",0,1) -> 109 | T17: =_xlfn.XLOOKUP(A:A,'[4]TD90D PZAS'!$A:$A,'[4]TD90D PZAS'!$CX:$CX,"",0,1) -> 6 | U17: =_xlfn.XLOOKUP(A:A,'[4]TD90D PZAS'!$A:$A,'[4]TD90D PZAS'!$DA:$DA,"",0,1) -> 14
A18: 2398 | B18: =_xlfn.XLOOKUP(A:A,[1]Hoja1!$C:$C,[1]Hoja1!$D:$D,"",0,1) -> AEROSOL NEGRO MATE | C18: 18 | D18: =_xlfn.XLOOKUP(A:A,[2]Hoja1!$C:$C,[2]Hoja1!$H:$H,"",0,1) -> 55.17 | E18: =_xlfn.XLOOKUP(A:A,[1]Hoja1!$C:$C,[1]Hoja1!$H:$H,"",0,1) -> 41.38 | F18: =_xlfn.XLOOKUP(A:A,TD!A:A,TD!EC:EC,"",0,1) -> 5.3333333 | G18: =INT(F18) -> 5 | H18: =D18*$G$5 -> 165.51 | I18: =E18*$G$5 -> 124.14 | J18: 2398 | K18: =_xlfn.XLOOKUP(J:J,'[3]FILTROS 2'!$A:$A,'[3]FILTROS 2'!$E:$E,"",0,1) -> AEROSOLES PRISA | L18: 5 | M18: =L18*D18 -> 275.85 | N18: =$L18*E18 -> 206.9 | O18: =_xlfn.XLOOKUP(A:A,[4]TD90D!$A:$A,[4]TD90D!$CW:$CW,"",0,1) -> 26 | P18: =_xlfn.XLOOKUP(A:A,[4]TD90D!$A:$A,[4]TD90D!$CX:$CX,"",0,1) -> 10 | Q18: =_xlfn.XLOOKUP(A:A,[4]TD90D!$A:$A,[4]TD90D!$DA:$DA,"",0,1) -> 0 | R18: =P18/C18 -> 0.55555556 | S18: =_xlfn.XLOOKUP(A:A,'[4]TD90D PZAS'!$A:$A,'[4]TD90D PZAS'!$CW:$CW,"",0,1) -> 156 | T18: =_xlfn.XLOOKUP(A:A,'[4]TD90D PZAS'!$A:$A,'[4]TD90D PZAS'!$CX:$CX,"",0,1) -> 9 | U18: =_xlfn.XLOOKUP(A:A,'[4]TD90D PZAS'!$A:$A,'[4]TD90D PZAS'!$DA:$DA,"",0,1) -> 13
A19: IG-30563 | B19: =_xlfn.XLOOKUP(A:A,[1]Hoja1!$C:$C,[1]Hoja1!$D:$D,"",0,1) -> IMPERGLOSI AGUACERO TERRACOTA 3A | C19: 16 | D19: =_xlfn.XLOOKUP(A:A,[2]Hoja1!$C:$C,[2]Hoja1!$H:$H,"",0,1) -> 225 | E19: =_xlfn.XLOOKUP(A:A,[1]Hoja1!$C:$C,[1]Hoja1!$H:$H,"",0,1) -> 179.31 | F19: =_xlfn.XLOOKUP(A:A,TD!A:A,TD!EC:EC,"",0,1) -> 3.125 | G19: =INT(F19) -> 3 | H19: =D19*$G$5 -> 675 | I19: =E19*$G$5 -> 537.93 | J19: IG-30563 | K19: =_xlfn.XLOOKUP(J:J,'[3]FILTROS 2'!$A:$A,'[3]FILTROS 2'!$E:$E,"",0,1) -> IMPERGLOSI AGUACERO 3 AÑOS | M19: =L19*D19 -> 0 | N19: =$L19*E19 -> 0 | O19: =_xlfn.XLOOKUP(A:A,[4]TD90D!$A:$A,[4]TD90D!$CW:$CW,"",0,1) -> 11 | P19: =_xlfn.XLOOKUP(A:A,[4]TD90D!$A:$A,[4]TD90D!$CX:$CX,"",0,1) -> 5 | Q19: =_xlfn.XLOOKUP(A:A,[4]TD90D!$A:$A,[4]TD90D!$DA:$DA,"",0,1) -> 0 | R19: =P19/C19 -> 0.3125 | S19: =_xlfn.XLOOKUP(A:A,'[4]TD90D PZAS'!$A:$A,'[4]TD90D PZAS'!$CW:$CW,"",0,1) -> 25 | T19: =_xlfn.XLOOKUP(A:A,'[4]TD90D PZAS'!$A:$A,'[4]TD90D PZAS'!$CX:$CX,"",0,1) -> 3 | U19: =_xlfn.XLOOKUP(A:A,'[4]TD90D PZAS'!$A:$A,'[4]TD90D PZAS'!$DA:$DA,"",0,1) -> 0
A20: 2390 | B20: =_xlfn.XLOOKUP(A:A,[1]Hoja1!$C:$C,[1]Hoja1!$D:$D,"",0,1) -> AEROSOL ALUMINIO | C20: 14 | D20: =_xlfn.XLOOKUP(A:A,[2]Hoja1!$C:$C,[2]Hoja1!$H:$H,"",0,1) -> 55.17 | E20: =_xlfn.XLOOKUP(A:A,[1]Hoja1!$C:$C,[1]Hoja1!$H:$H,"",0,1) -> 41.38 | F20: =_xlfn.XLOOKUP(A:A,TD!A:A,TD!EC:EC,"",0,1) -> 3.5714286 | G20: =INT(F20) -> 3 | H20: =D20*$G$5 -> 165.51 | I20: =E20*$G$5 -> 124.14 | J20: 2390 | K20: =_xlfn.XLOOKUP(J:J,'[3]FILTROS 2'!$A:$A,'[3]FILTROS 2'!$E:$E,"",0,1) -> AEROSOLES PRISA | L20: 3 | M20: =L20*D20 -> 165.51 | N20: =$L20*E20 -> 124.14 | O20: =_xlfn.XLOOKUP(A:A,[4]TD90D!$A:$A,[4]TD90D!$CW:$CW,"",0,1) -> 16 | P20: =_xlfn.XLOOKUP(A:A,[4]TD90D!$A:$A,[4]TD90D!$CX:$CX,"",0,1) -> 6 | Q20: =_xlfn.XLOOKUP(A:A,[4]TD90D!$A:$A,[4]TD90D!$DA:$DA,"",0,1) -> 0 | R20: =P20/C20 -> 0.42857143 | S20: =_xlfn.XLOOKUP(A:A,'[4]TD90D PZAS'!$A:$A,'[4]TD90D PZAS'!$CW:$CW,"",0,1) -> 45 | T20: =_xlfn.XLOOKUP(A:A,'[4]TD90D PZAS'!$A:$A,'[4]TD90D PZAS'!$CX:$CX,"",0,1) -> 4 | U20: =_xlfn.XLOOKUP(A:A,'[4]TD90D PZAS'!$A:$A,'[4]TD90D PZAS'!$DA:$DA,"",0,1) -> 0
A21: SRG-10994 | B21: =_xlfn.XLOOKUP(A:A,[1]Hoja1!$C:$C,[1]Hoja1!$D:$D,"",0,1) -> ESMALTE GLOSI SR NEGRO BRILLANTE | C21: 14 | D21: =_xlfn.XLOOKUP(A:A,[2]Hoja1!$C:$C,[2]Hoja1!$H:$H,"",0,1) -> 205.17 | E21: =_xlfn.XLOOKUP(A:A,[1]Hoja1!$C:$C,[1]Hoja1!$H:$H,"",0,1) -> 161.21 | F21: =_xlfn.XLOOKUP(A:A,TD!A:A,TD!EC:EC,"",0,1) -> 5.0714286 | G21: =INT(F21) -> 5 | H21: =D21*$G$5 -> 615.51 | I21: =E21*$G$5 -> 483.63 | J21: SRG-10994 | K21: =_xlfn.XLOOKUP(J:J,'[3]FILTROS 2'!$A:$A,'[3]FILTROS 2'!$E:$E,"",0,1) -> ESMALTE - GLOSI SECADO RAPIDO | M21: =L21*D21 -> 0 | N21: =$L21*E21 -> 0 | O21: =_xlfn.XLOOKUP(A:A,[4]TD90D!$A:$A,[4]TD90D!$CW:$CW,"",0,1) -> 10 | P21: =_xlfn.XLOOKUP(A:A,[4]TD90D!$A:$A,[4]TD90D!$CX:$CX,"",0,1) -> 5 | Q21: =_xlfn.XLOOKUP(A:A,[4]TD90D!$A:$A,[4]TD90D!$DA:$DA,"",0,1) -> 0 | R21: =P21/C21 -> 0.35714286 | S21: =_xlfn.XLOOKUP(A:A,'[4]TD90D PZAS'!$A:$A,'[4]TD90D PZAS'!$CW:$CW,"",0,1) -> 66 | T21: =_xlfn.XLOOKUP(A:A,'[4]TD90D PZAS'!$A:$A,'[4]TD90D PZAS'!$CX:$CX,"",0,1) -> 5 | U21: =_xlfn.XLOOKUP(A:A,'[4]TD90D PZAS'!$A:$A,'[4]TD90D PZAS'!$DA:$DA,"",0,1) -> 0
A22: VG-50013 | B22: =_xlfn.XLOOKUP(A:A,[1]Hoja1!$C:$C,[1]Hoja1!$D:$D,"",0,1) -> VINILICA GLOSI BLANCO ULTRA | C22: 14 | D22: =_xlfn.XLOOKUP(A:A,[2]Hoja1!$C:$C,[2]Hoja1!$H:$H,"",0,1) -> 299.14 | E22: =_xlfn.XLOOKUP(A:A,[1]Hoja1!$C:$C,[1]Hoja1!$H:$H,"",0,1) -> 224.14 | F22: =_xlfn.XLOOKUP(A:A,TD!A:A,TD!EC:EC,"",0,1) -> 2.4285714 | G22: =INT(F22) -> 2 | H22: =D22*$G$5 -> 897.42 | I22: =E22*$G$5 -> 672.42 | J22: VG-50013 | K22: =_xlfn.XLOOKUP(J:J,'[3]FILTROS 2'!$A:$A,'[3]FILTROS 2'!$E:$E,"",0,1) -> VINILICA - GLOSI 3 AÑOS | L22: 8 | M22: =L22*D22 -> 2393.12 | N22: =$L22*E22 -> 1793.12 | O22: =_xlfn.XLOOKUP(A:A,[4]TD90D!$A:$A,[4]TD90D!$CW:$CW,"",0,1) -> 13 | P22: =_xlfn.XLOOKUP(A:A,[4]TD90D!$A:$A,[4]TD90D!$CX:$CX,"",0,1) -> 6 | Q22: =_xlfn.XLOOKUP(A:A,[4]TD90D!$A:$A,[4]TD90D!$DA:$DA,"",0,1) -> 0 | R22: =P22/C22 -> 0.42857143 | S22: =_xlfn.XLOOKUP(A:A,'[4]TD90D PZAS'!$A:$A,'[4]TD90D PZAS'!$CW:$CW,"",0,1) -> 39 | T22: =_xlfn.XLOOKUP(A:A,'[4]TD90D PZAS'!$A:$A,'[4]TD90D PZAS'!$CX:$CX,"",0,1) -> 5 | U22: =_xlfn.XLOOKUP(A:A,'[4]TD90D PZAS'!$A:$A,'[4]TD90D PZAS'!$DA:$DA,"",0,1) -> 0
A23: SRG-10004 | B23: =_xlfn.XLOOKUP(A:A,[1]Hoja1!$C:$C,[1]Hoja1!$D:$D,"",0,1) -> ESMALTE GLOSI SR BLANCO | C23: 14 | D23: =_xlfn.XLOOKUP(A:A,[2]Hoja1!$C:$C,[2]Hoja1!$H:$H,"",0,1) -> 205.17 | E23: =_xlfn.XLOOKUP(A:A,[1]Hoja1!$C:$C,[1]Hoja1!$H:$H,"",0,1) -> 161.21 | F23: =_xlfn.XLOOKUP(A:A,TD!A:A,TD!EC:EC,"",0,1) -> 4.2142857 | G23: =INT(F23) -> 4 | H23: =D23*$G$5 -> 615.51 | I23: =E23*$G$5 -> 483.63 | J23: SRG-10004 | K23: =_xlfn.XLOOKUP(J:J,'[3]FILTROS 2'!$A:$A,'[3]FILTROS 2'!$E:$E,"",0,1) -> ESMALTE - GLOSI SECADO RAPIDO | O23: =_xlfn.XLOOKUP(A:A,[4]TD90D!$A:$A,[4]TD90D!$CW:$CW,"",0,1) -> 6 | P23: =_xlfn.XLOOKUP(A:A,[4]TD90D!$A:$A,[4]TD90D!$CX:$CX,"",0,1) -> 3 | Q23: =_xlfn.XLOOKUP(A:A,[4]TD90D!$A:$A,[4]TD90D!$DA:$DA,"",0,1) -> 0 | R23: =P23/C23 -> 0.21428571 | S23: =_xlfn.XLOOKUP(A:A,'[4]TD90D PZAS'!$A:$A,'[4]TD90D PZAS'!$CW:$CW,"",0,1) -> 28 | T23: =_xlfn.XLOOKUP(A:A,'[4]TD90D PZAS'!$A:$A,'[4]TD90D PZAS'!$CX:$CX,"",0,1) -> 3 | U23: =_xlfn.XLOOKUP(A:A,'[4]TD90D PZAS'!$A:$A,'[4]TD90D PZAS'!$DA:$DA,"",0,1) -> 0
A24: IG-50001 | B24: =_xlfn.XLOOKUP(A:A,[1]Hoja1!$C:$C,[1]Hoja1!$D:$D,"",0,1) -> IMPERGLOSI AGUACERO BLANCO 5A | C24: 13 | D24: =_xlfn.XLOOKUP(A:A,[2]Hoja1!$C:$C,[2]Hoja1!$H:$H,"",0,1) -> 1118.97 | E24: =_xlfn.XLOOKUP(A:A,[1]Hoja1!$C:$C,[1]Hoja1!$H:$H,"",0,1) -> 896.55 | F24: =_xlfn.XLOOKUP(A:A,TD!A:A,TD!EC:EC,"",0,1) -> 7 | G24: =INT(F24) -> 7 | H24: =D24*$G$5 -> 3356.91 | I24: =E24*$G$5 -> 2689.65 | J24: IG-50001 | K24: =_xlfn.XLOOKUP(J:J,'[3]FILTROS 2'!$A:$A,'[3]FILTROS 2'!$E:$E,"",0,1) -> IMPERGLOSI AGUACERO 5 AÑOS | O24: =_xlfn.XLOOKUP(A:A,[4]TD90D!$A:$A,[4]TD90D!$CW:$CW,"",0,1) -> 4 | P24: =_xlfn.XLOOKUP(A:A,[4]TD90D!$A:$A,[4]TD90D!$CX:$CX,"",0,1) -> 2 | Q24: =_xlfn.XLOOKUP(A:A,[4]TD90D!$A:$A,[4]TD90D!$DA:$DA,"",0,1) -> 0 | R24: =P24/C24 -> 0.15384615 | S24: =_xlfn.XLOOKUP(A:A,'[4]TD90D PZAS'!$A:$A,'[4]TD90D PZAS'!$CW:$CW,"",0,1) -> 63 | T24: =_xlfn.XLOOKUP(A:A,'[4]TD90D PZAS'!$A:$A,'[4]TD90D PZAS'!$CX:$CX,"",0,1) -> 2 | U24: =_xlfn.XLOOKUP(A:A,'[4]TD90D PZAS'!$A:$A,'[4]TD90D PZAS'!$DA:$DA,"",0,1) -> 0
A25: VG-50011 | B25: =_xlfn.XLOOKUP(A:A,[1]Hoja1!$C:$C,[1]Hoja1!$D:$D,"",0,1) -> VINILICA GLOSI BLANCO ULTRA | C25: 13 | D25: =_xlfn.XLOOKUP(A:A,[2]Hoja1!$C:$C,[2]Hoja1!$H:$H,"",0,1) -> 1213.79 | E25: =_xlfn.XLOOKUP(A:A,[1]Hoja1!$C:$C,[1]Hoja1!$H:$H,"",0,1) -> 909.48 | F25: =_xlfn.XLOOKUP(A:A,TD!A:A,TD!EC:EC,"",0,1) -> 1.8461538 | G25: =INT(F25) -> 1 | H25: =D25*$G$5 -> 3641.37 | I25: =E25*$G$5 -> 2728.44 | J25: VG-50011 | K25: =_xlfn.XLOOKUP(J:J,'[3]FILTROS 2'!$A:$A,'[3]FILTROS 2'!$E:$E,"",0,1) -> VINILICA - GLOSI 3 AÑOS | O25: =_xlfn.XLOOKUP(A:A,[4]TD90D!$A:$A,[4]TD90D!$CW:$CW,"",0,1) -> 10 | P25: =_xlfn.XLOOKUP(A:A,[4]TD90D!$A:$A,[4]TD90D!$CX:$CX,"",0,1) -> 5 | Q25: =_xlfn.XLOOKUP(A:A,[4]TD90D!$A:$A,[4]TD90D!$DA:$DA,"",0,1) -> 0 | R25: =P25/C25 -> 0.38461538 | S25: =_xlfn.XLOOKUP(A:A,'[4]TD90D PZAS'!$A:$A,'[4]TD90D PZAS'!$CW:$CW,"",0,1) -> 36 | T25: =_xlfn.XLOOKUP(A:A,'[4]TD90D PZAS'!$A:$A,'[4]TD90D PZAS'!$CX:$CX,"",0,1) -> 5 | U25: =_xlfn.XLOOKUP(A:A,'[4]TD90D PZAS'!$A:$A,'[4]TD90D PZAS'!$DA:$DA,"",0,1) -> 0
A26: IG-30003 | B26: =_xlfn.XLOOKUP(A:A,[1]Hoja1!$C:$C,[1]Hoja1!$D:$D,"",0,1) -> IMPERGLOSI AGUACERO BLANCO 3A | C26: 12 | D26: =_xlfn.XLOOKUP(A:A,[2]Hoja1!$C:$C,[2]Hoja1!$H:$H,"",0,1) -> 225 | E26: =_xlfn.XLOOKUP(A:A,[1]Hoja1!$C:$C,[1]Hoja1!$H:$H,"",0,1) -> 179.31 | F26: =_xlfn.XLOOKUP(A:A,TD!A:A,TD!EC:EC,"",0,1) -> 2.75 | G26: =INT(F26) -> 2 | H26: =D26*$G$5 -> 675 | I26: =E26*$G$5 -> 537.93 | J26: IG-30003 | K26: =_xlfn.XLOOKUP(J:J,'[3]FILTROS 2'!$A:$A,'[3]FILTROS 2'!$E:$E,"",0,1) -> IMPERGLOSI AGUACERO 3 AÑOS | O26: =_xlfn.XLOOKUP(A:A,[4]TD90D!$A:$A,[4]TD90D!$CW:$CW,"",0,1) -> 2 | P26: =_xlfn.XLOOKUP(A:A,[4]TD90D!$A:$A,[4]TD90D!$CX:$CX,"",0,1) -> 1 | Q26: =_xlfn.XLOOKUP(A:A,[4]TD90D!$A:$A,[4]TD90D!$DA:$DA,"",0,1) -> 0 | R26: =P26/C26 -> 0.083333333 | S26: =_xlfn.XLOOKUP(A:A,'[4]TD90D PZAS'!$A:$A,'[4]TD90D PZAS'!$CW:$CW,"",0,1) -> 0 | T26: =_xlfn.XLOOKUP(A:A,'[4]TD90D PZAS'!$A:$A,'[4]TD90D PZAS'!$CX:$CX,"",0,1) -> 0 | U26: =_xlfn.XLOOKUP(A:A,'[4]TD90D PZAS'!$A:$A,'[4]TD90D PZAS'!$DA:$DA,"",0,1) -> 0
A27: 2345 | B27: =_xlfn.XLOOKUP(A:A,[1]Hoja1!$C:$C,[1]Hoja1!$D:$D,"",0,1) -> AEROSOL ROJO | C27: 11 | D27: =_xlfn.XLOOKUP(A:A,[2]Hoja1!$C:$C,[2]Hoja1!$H:$H,"",0,1) -> 55.17 | E27: =_xlfn.XLOOKUP(A:A,[1]Hoja1!$C:$C,[1]Hoja1!$H:$H,"",0,1) -> 41.38 | F27: =_xlfn.XLOOKUP(A:A,TD!A:A,TD!EC:EC,"",0,1) -> 4.9090909 | G27: =INT(F27) -> 4 | H27: =D27*$G$5 -> 165.51 | I27: =E27*$G$5 -> 124.14 | J27: 2345 | K27: =_xlfn.XLOOKUP(J:J,'[3]FILTROS 2'!$A:$A,'[3]FILTROS 2'!$E:$E,"",0,1) -> AEROSOLES PRISA | O27: =_xlfn.XLOOKUP(A:A,[4]TD90D!$A:$A,[4]TD90D!$CW:$CW,"",0,1) -> 16 | P27: =_xlfn.XLOOKUP(A:A,[4]TD90D!$A:$A,[4]TD90D!$CX:$CX,"",0,1) -> 6 | Q27: =_xlfn.XLOOKUP(A:A,[4]TD90D!$A:$A,[4]TD90D!$DA:$DA,"",0,1) -> 0 | R27: =P27/C27 -> 0.54545455 | S27: =_xlfn.XLOOKUP(A:A,'[4]TD90D PZAS'!$A:$A,'[4]TD90D PZAS'!$CW:$CW,"",0,1) -> 61 | T27: =_xlfn.XLOOKUP(A:A,'[4]TD90D PZAS'!$A:$A,'[4]TD90D PZAS'!$CX:$CX,"",0,1) -> 4 | U27: =_xlfn.XLOOKUP(A:A,'[4]TD90D PZAS'!$A:$A,'[4]TD90D PZAS'!$DA:$DA,"",0,1) -> 0
A28: SRG-10003 | B28: =_xlfn.XLOOKUP(A:A,[1]Hoja1!$C:$C,[1]Hoja1!$D:$D,"",0,1) -> ESMALTE GLOSI SR BLANCO | C28: 11 | D28: =_xlfn.XLOOKUP(A:A,[2]Hoja1!$C:$C,[2]Hoja1!$H:$H,"",0,1) -> 730.17 | E28: =_xlfn.XLOOKUP(A:A,[1]Hoja1!$C:$C,[1]Hoja1!$H:$H,"",0,1) -> 584.48 | F28: =_xlfn.XLOOKUP(A:A,TD!A:A,TD!EC:EC,"",0,1) -> 1.7272727 | G28: =INT(F28) -> 1 | H28: =D28*$G$5 -> 2190.51 | I28: =E28*$G$5 -> 1753.44 | J28: SRG-10003 | K28: =_xlfn.XLOOKUP(J:J,'[3]FILTROS 2'!$A:$A,'[3]FILTROS 2'!$E:$E,"",0,1) -> ESMALTE - GLOSI SECADO RAPIDO | O28: =_xlfn.XLOOKUP(A:A,[4]TD90D!$A:$A,[4]TD90D!$CW:$CW,"",0,1) -> 8 | P28: =_xlfn.XLOOKUP(A:A,[4]TD90D!$A:$A,[4]TD90D!$CX:$CX,"",0,1) -> 3 | Q28: =_xlfn.XLOOKUP(A:A,[4]TD90D!$A:$A,[4]TD90D!$DA:$DA,"",0,1) -> 0 | R28: =P28/C28 -> 0.27272727 | S28: =_xlfn.XLOOKUP(A:A,'[4]TD90D PZAS'!$A:$A,'[4]TD90D PZAS'!$CW:$CW,"",0,1) -> 19 | T28: =_xlfn.XLOOKUP(A:A,'[4]TD90D PZAS'!$A:$A,'[4]TD90D PZAS'!$CX:$CX,"",0,1) -> 3 | U28: =_xlfn.XLOOKUP(A:A,'[4]TD90D PZAS'!$A:$A,'[4]TD90D PZAS'!$DA:$DA,"",0,1) -> 0
A29: PRG-10934 | B29: =_xlfn.XLOOKUP(A:A,[1]Hoja1!$C:$C,[1]Hoja1!$D:$D,"",0,1) -> PRIMARIO GLOSI ESTRUCTURAS GRIS | C29: 11 | D29: =_xlfn.XLOOKUP(A:A,[2]Hoja1!$C:$C,[2]Hoja1!$H:$H,"",0,1) -> 138.79 | E29: =_xlfn.XLOOKUP(A:A,[1]Hoja1!$C:$C,[1]Hoja1!$H:$H,"",0,1) -> 105.17 | F29: =_xlfn.XLOOKUP(A:A,TD!A:A,TD!EC:EC,"",0,1) -> 3 | G29: =INT(F29) -> 3 | H29: =D29*$G$5 -> 416.37 | I29: =E29*$G$5 -> 315.51 | J29: PRG-10934 | K29: =_xlfn.XLOOKUP(J:J,'[3]FILTROS 2'!$A:$A,'[3]FILTROS 2'!$E:$E,"",0,1) -> ESMALTE - ESTRUCTURAS GLOSI | O29: =_xlfn.XLOOKUP(A:A,[4]TD90D!$A:$A,[4]TD90D!$CW:$CW,"",0,1) -> 2 | P29: =_xlfn.XLOOKUP(A:A,[4]TD90D!$A:$A,[4]TD90D!$CX:$CX,"",0,1) -> 1 | Q29: =_xlfn.XLOOKUP(A:A,[4]TD90D!$A:$A,[4]TD90D!$DA:$DA,"",0,1) -> 0 | R29: =P29/C29 -> 0.090909091 | S29: =_xlfn.XLOOKUP(A:A,'[4]TD90D PZAS'!$A:$A,'[4]TD90D PZAS'!$CW:$CW,"",0,1) -> 3 | T29: =_xlfn.XLOOKUP(A:A,'[4]TD90D PZAS'!$A:$A,'[4]TD90D PZAS'!$CX:$CX,"",0,1) -> 1 | U29: =_xlfn.XLOOKUP(A:A,'[4]TD90D PZAS'!$A:$A,'[4]TD90D PZAS'!$DA:$DA,"",0,1) -> 0
A30: 2397 | B30: =_xlfn.XLOOKUP(A:A,[1]Hoja1!$C:$C,[1]Hoja1!$D:$D,"",0,1) -> AEROSOL NEGRO SEMI BRILLANTE | C30: 11 | D30: =_xlfn.XLOOKUP(A:A,[2]Hoja1!$C:$C,[2]Hoja1!$H:$H,"",0,1) -> 55.17 | E30: =_xlfn.XLOOKUP(A:A,[1]Hoja1!$C:$C,[1]Hoja1!$H:$H,"",0,1) -> 41.38 | F30: =_xlfn.XLOOKUP(A:A,TD!A:A,TD!EC:EC,"",0,1) -> 5.4545455 | G30: =INT(F30) -> 5 | H30: =D30*$G$5 -> 165.51 | I30: =E30*$G$5 -> 124.14 | J30: 2397 | K30: =_xlfn.XLOOKUP(J:J,'[3]FILTROS 2'!$A:$A,'[3]FILTROS 2'!$E:$E,"",0,1) -> AEROSOLES PRISA | O30: =_xlfn.XLOOKUP(A:A,[4]TD90D!$A:$A,[4]TD90D!$CW:$CW,"",0,1) -> 11 | P30: =_xlfn.XLOOKUP(A:A,[4]TD90D!$A:$A,[4]TD90D!$CX:$CX,"",0,1) -> 5 | Q30: =_xlfn.XLOOKUP(A:A,[4]TD90D!$A:$A,[4]TD90D!$DA:$DA,"",0,1) -> 0 | R30: =P30/C30 -> 0.45454545 | S30: =_xlfn.XLOOKUP(A:A,'[4]TD90D PZAS'!$A:$A,'[4]TD90D PZAS'!$CW:$CW,"",0,1) -> 97 | T30: =_xlfn.XLOOKUP(A:A,'[4]TD90D PZAS'!$A:$A,'[4]TD90D PZAS'!$CX:$CX,"",0,1) -> 4 | U30: =_xlfn.XLOOKUP(A:A,'[4]TD90D PZAS'!$A:$A,'[4]TD90D PZAS'!$DA:$DA,"",0,1) -> 0
A31: 2451 | B31: =_xlfn.XLOOKUP(A:A,[1]Hoja1!$C:$C,[1]Hoja1!$D:$D,"",0,1) -> AEROSOL SUPER ORO | C31: 10 | D31: =_xlfn.XLOOKUP(A:A,[2]Hoja1!$C:$C,[2]Hoja1!$H:$H,"",0,1) -> 73.28 | E31: =_xlfn.XLOOKUP(A:A,[1]Hoja1!$C:$C,[1]Hoja1!$H:$H,"",0,1) -> 55.17 | F31: =_xlfn.XLOOKUP(A:A,TD!A:A,TD!EC:EC,"",0,1) -> 5.5 | G31: =INT(F31) -> 5 | H31: =D31*$G$5 -> 219.84 | I31: =E31*$G$5 -> 165.51 | J31: 2451 | K31: =_xlfn.XLOOKUP(J:J,'[3]FILTROS 2'!$A:$A,'[3]FILTROS 2'!$E:$E,"",0,1) -> AEROSOLES PRISA | O31: =_xlfn.XLOOKUP(A:A,[4]TD90D!$A:$A,[4]TD90D!$CW:$CW,"",0,1) -> 6 | P31: =_xlfn.XLOOKUP(A:A,[4]TD90D!$A:$A,[4]TD90D!$CX:$CX,"",0,1) -> 2 | Q31: =_xlfn.XLOOKUP(A:A,[4]TD90D!$A:$A,[4]TD90D!$DA:$DA,"",0,1) -> 0 | R31: =P31/C31 -> 0.2 | S31: =_xlfn.XLOOKUP(A:A,'[4]TD90D PZAS'!$A:$A,'[4]TD90D PZAS'!$CW:$CW,"",0,1) -> 12 | T31: =_xlfn.XLOOKUP(A:A,'[4]TD90D PZAS'!$A:$A,'[4]TD90D PZAS'!$CX:$CX,"",0,1) -> 1 | U31: =_xlfn.XLOOKUP(A:A,'[4]TD90D PZAS'!$A:$A,'[4]TD90D PZAS'!$DA:$DA,"",0,1) -> 0
A32: 28014 | B32: =_xlfn.XLOOKUP(A:A,[1]Hoja1!$C:$C,[1]Hoja1!$D:$D,"",0,1) -> BRILLON BLANCO MATE | C32: 10 | D32: =_xlfn.XLOOKUP(A:A,[2]Hoja1!$C:$C,[2]Hoja1!$H:$H,"",0,1) -> 150.86 | E32: =_xlfn.XLOOKUP(A:A,[1]Hoja1!$C:$C,[1]Hoja1!$H:$H,"",0,1) -> 112.93 | F32: =_xlfn.XLOOKUP(A:A,TD!A:A,TD!EC:EC,"",0,1) -> 3.7 | G32: =INT(F32) -> 3 | H32: =D32*$G$5 -> 452.58 | I32: =E32*$G$5 -> 338.79 | J32: 28014 | K32: =_xlfn.XLOOKUP(J:J,'[3]FILTROS 2'!$A:$A,'[3]FILTROS 2'!$E:$E,"",0,1) -> ESMALTE - BRILLON | O32: =_xlfn.XLOOKUP(A:A,[4]TD90D!$A:$A,[4]TD90D!$CW:$CW,"",0,1) -> 8 | P32: =_xlfn.XLOOKUP(A:A,[4]TD90D!$A:$A,[4]TD90D!$CX:$CX,"",0,1) -> 4 | Q32: =_xlfn.XLOOKUP(A:A,[4]TD90D!$A:$A,[4]TD90D!$DA:$DA,"",0,1) -> 0 | R32: =P32/C32 -> 0.4 | S32: =_xlfn.XLOOKUP(A:A,'[4]TD90D PZAS'!$A:$A,'[4]TD90D PZAS'!$CW:$CW,"",0,1) -> 28 | T32: =_xlfn.XLOOKUP(A:A,'[4]TD90D PZAS'!$A:$A,'[4]TD90D PZAS'!$CX:$CX,"",0,1) -> 3 | U32: =_xlfn.XLOOKUP(A:A,'[4]TD90D PZAS'!$A:$A,'[4]TD90D PZAS'!$DA:$DA,"",0,1) -> 0
A33: VG-50014 | B33: =_xlfn.XLOOKUP(A:A,[1]Hoja1!$C:$C,[1]Hoja1!$D:$D,"",0,1) -> VINILICA GLOSI BLANCO ULTRA | C33: 10 | D33: =_xlfn.XLOOKUP(A:A,[2]Hoja1!$C:$C,[2]Hoja1!$H:$H,"",0,1) -> 107.76 | E33: =_xlfn.XLOOKUP(A:A,[1]Hoja1!$C:$C,[1]Hoja1!$H:$H,"",0,1) -> 78.45 | F33: =_xlfn.XLOOKUP(A:A,TD!A:A,TD!EC:EC,"",0,1) -> 3.9 | G33: =INT(F33) -> 3 | H33: =D33*$G$5 -> 323.28 | I33: =E33*$G$5 -> 235.35 | J33: VG-50014 | K33: =_xlfn.XLOOKUP(J:J,'[3]FILTROS 2'!$A:$A,'[3]FILTROS 2'!$E:$E,"",0,1) -> VINILICA - GLOSI 3 AÑOS | O33: =_xlfn.XLOOKUP(A:A,[4]TD90D!$A:$A,[4]TD90D!$CW:$CW,"",0,1) -> 9 | P33: =_xlfn.XLOOKUP(A:A,[4]TD90D!$A:$A,[4]TD90D!$CX:$CX,"",0,1) -> 4 | Q33: =_xlfn.XLOOKUP(A:A,[4]TD90D!$A:$A,[4]TD90D!$DA:$DA,"",0,1) -> 0 | R33: =P33/C33 -> 0.4 | S33: =_xlfn.XLOOKUP(A:A,'[4]TD90D PZAS'!$A:$A,'[4]TD90D PZAS'!$CW:$CW,"",0,1) -> 45 | T33: =_xlfn.XLOOKUP(A:A,'[4]TD90D PZAS'!$A:$A,'[4]TD90D PZAS'!$CX:$CX,"",0,1) -> 4 | U33: =_xlfn.XLOOKUP(A:A,'[4]TD90D PZAS'!$A:$A,'[4]TD90D PZAS'!$DA:$DA,"",0,1) -> 0
A34: 28916 | B34: =_xlfn.XLOOKUP(A:A,[1]Hoja1!$C:$C,[1]Hoja1!$D:$D,"",0,1) -> BRILLON DORADO | C34: 9 | D34: =_xlfn.XLOOKUP(A:A,[2]Hoja1!$C:$C,[2]Hoja1!$H:$H,"",0,1) -> 58.62 | E34: =_xlfn.XLOOKUP(A:A,[1]Hoja1!$C:$C,[1]Hoja1!$H:$H,"",0,1) -> 43.97 | F34: =_xlfn.XLOOKUP(A:A,TD!A:A,TD!EC:EC,"",0,1) -> 4.1111111 | G34: =INT(F34) -> 4 | H34: =D34*$G$5 -> 175.86 | I34: =E34*$G$5 -> 131.91 | J34: 28916 | K34: =_xlfn.XLOOKUP(J:J,'[3]FILTROS 2'!$A:$A,'[3]FILTROS 2'!$E:$E,"",0,1) -> ESMALTE - BRILLON | O34: =_xlfn.XLOOKUP(A:A,[4]TD90D!$A:$A,[4]TD90D!$CW:$CW,"",0,1) -> 5 | P34: =_xlfn.XLOOKUP(A:A,[4]TD90D!$A:$A,[4]TD90D!$CX:$CX,"",0,1) -> 2 | Q34: =_xlfn.XLOOKUP(A:A,[4]TD90D!$A:$A,[4]TD90D!$DA:$DA,"",0,1) -> 0 | R34: =P34/C34 -> 0.22222222 | S34: =_xlfn.XLOOKUP(A:A,'[4]TD90D PZAS'!$A:$A,'[4]TD90D PZAS'!$CW:$CW,"",0,1) -> 18 | T34: =_xlfn.XLOOKUP(A:A,'[4]TD90D PZAS'!$A:$A,'[4]TD90D PZAS'!$CX:$CX,"",0,1) -> 2 | U34: =_xlfn.XLOOKUP(A:A,'[4]TD90D PZAS'!$A:$A,'[4]TD90D PZAS'!$DA:$DA,"",0,1) -> 0
A35: 28586 | B35: =_xlfn.XLOOKUP(A:A,[1]Hoja1!$C:$C,[1]Hoja1!$D:$D,"",0,1) -> BRILLON CACAO | C35: 9 | D35: =_xlfn.XLOOKUP(A:A,[2]Hoja1!$C:$C,[2]Hoja1!$H:$H,"",0,1) -> 58.62 | E35: =_xlfn.XLOOKUP(A:A,[1]Hoja1!$C:$C,[1]Hoja1!$H:$H,"",0,1) -> 43.97 | F35: =_xlfn.XLOOKUP(A:A,TD!A:A,TD!EC:EC,"",0,1) -> 5.3333333 | G35: =INT(F35) -> 5 | H35: =D35*$G$5 -> 175.86 | I35: =E35*$G$5 -> 131.91 | J35: 28586 | K35: =_xlfn.XLOOKUP(J:J,'[3]FILTROS 2'!$A:$A,'[3]FILTROS 2'!$E:$E,"",0,1) -> ESMALTE - BRILLON | O35: =_xlfn.XLOOKUP(A:A,[4]TD90D!$A:$A,[4]TD90D!$CW:$CW,"",0,1) -> 6 | P35: =_xlfn.XLOOKUP(A:A,[4]TD90D!$A:$A,[4]TD90D!$CX:$CX,"",0,1) -> 2 | Q35: =_xlfn.XLOOKUP(A:A,[4]TD90D!$A:$A,[4]TD90D!$DA:$DA,"",0,1) -> 0 | R35: =P35/C35 -> 0.22222222 | S35: =_xlfn.XLOOKUP(A:A,'[4]TD90D PZAS'!$A:$A,'[4]TD90D PZAS'!$CW:$CW,"",0,1) -> 12 | T35: =_xlfn.XLOOKUP(A:A,'[4]TD90D PZAS'!$A:$A,'[4]TD90D PZAS'!$CX:$CX,"",0,1) -> 2 | U35: =_xlfn.XLOOKUP(A:A,'[4]TD90D PZAS'!$A:$A,'[4]TD90D PZAS'!$DA:$DA,"",0,1) -> 0
A36: VG-30011 | B36: =_xlfn.XLOOKUP(A:A,[1]Hoja1!$C:$C,[1]Hoja1!$D:$D,"",0,1) -> VINILICA GLOSI BLANCO BASIC | C36: 9 | D36: =_xlfn.XLOOKUP(A:A,[2]Hoja1!$C:$C,[2]Hoja1!$H:$H,"",0,1) -> 874.14 | E36: =_xlfn.XLOOKUP(A:A,[1]Hoja1!$C:$C,[1]Hoja1!$H:$H,"",0,1) -> 656.03 | F36: =_xlfn.XLOOKUP(A:A,TD!A:A,TD!EC:EC,"",0,1) -> 2.2222222 | G36: =INT(F36) -> 2 | H36: =D36*$G$5 -> 2622.42 | I36: =E36*$G$5 -> 1968.09 | J36: VG-30011 | K36: =_xlfn.XLOOKUP(J:J,'[3]FILTROS 2'!$A:$A,'[3]FILTROS 2'!$E:$E,"",0,1) -> VINILICA - GLOSI 3 AÑOS | O36: =_xlfn.XLOOKUP(A:A,[4]TD90D!$A:$A,[4]TD90D!$CW:$CW,"",0,1) -> 10 | P36: =_xlfn.XLOOKUP(A:A,[4]TD90D!$A:$A,[4]TD90D!$CX:$CX,"",0,1) -> 5 | Q36: =_xlfn.XLOOKUP(A:A,[4]TD90D!$A:$A,[4]TD90D!$DA:$DA,"",0,1) -> 0 | R36: =P36/C36 -> 0.55555556 | S36: =_xlfn.XLOOKUP(A:A,'[4]TD90D PZAS'!$A:$A,'[4]TD90D PZAS'!$CW:$CW,"",0,1) -> 24 | T36: =_xlfn.XLOOKUP(A:A,'[4]TD90D PZAS'!$A:$A,'[4]TD90D PZAS'!$CX:$CX,"",0,1) -> 5 | U36: =_xlfn.XLOOKUP(A:A,'[4]TD90D PZAS'!$A:$A,'[4]TD90D PZAS'!$DA:$DA,"",0,1) -> 0
A37: 28806 | B37: =_xlfn.XLOOKUP(A:A,[1]Hoja1!$C:$C,[1]Hoja1!$D:$D,"",0,1) -> BARNIZ ALQ. TRANSP. NATURAL | C37: 9 | D37: =_xlfn.XLOOKUP(A:A,[2]Hoja1!$C:$C,[2]Hoja1!$H:$H,"",0,1) -> 78.45 | E37: =_xlfn.XLOOKUP(A:A,[1]Hoja1!$C:$C,[1]Hoja1!$H:$H,"",0,1) -> 56.03 | F37: =_xlfn.XLOOKUP(A:A,TD!A:A,TD!EC:EC,"",0,1) -> 4.6666667 | G37: =INT(F37) -> 4 | H37: =D37*$G$5 -> 235.35 | I37: =E37*$G$5 -> 168.09 | J37: 28806 | K37: =_xlfn.XLOOKUP(J:J,'[3]FILTROS 2'!$A:$A,'[3]FILTROS 2'!$E:$E,"",0,1) -> BARNIZ ALQUIDALICO SIGLO | O37: =_xlfn.XLOOKUP(A:A,[4]TD90D!$A:$A,[4]TD90D!$CW:$CW,"",0,1) -> 8 | P37: =_xlfn.XLOOKUP(A:A,[4]TD90D!$A:$A,[4]TD90D!$CX:$CX,"",0,1) -> 3 | Q37: =_xlfn.XLOOKUP(A:A,[4]TD90D!$A:$A,[4]TD90D!$DA:$DA,"",0,1) -> 0 | R37: =P37/C37 -> 0.33333333 | S37: =_xlfn.XLOOKUP(A:A,'[4]TD90D PZAS'!$A:$A,'[4]TD90D PZAS'!$CW:$CW,"",0,1) -> 36 | T37: =_xlfn.XLOOKUP(A:A,'[4]TD90D PZAS'!$A:$A,'[4]TD90D PZAS'!$CX:$CX,"",0,1) -> 3 | U37: =_xlfn.XLOOKUP(A:A,'[4]TD90D PZAS'!$A:$A,'[4]TD90D PZAS'!$DA:$DA,"",0,1) -> 0
A38: 29012 | B38: =_xlfn.XLOOKUP(A:A,[1]Hoja1!$C:$C,[1]Hoja1!$D:$D,"",0,1) -> RELLENADOR AUTOMOTRIZ C/CATAL. ROJO | C38: 9 | D38: =_xlfn.XLOOKUP(A:A,[2]Hoja1!$C:$C,[2]Hoja1!$H:$H,"",0,1) -> 408.62 | E38: =_xlfn.XLOOKUP(A:A,[1]Hoja1!$C:$C,[1]Hoja1!$H:$H,"",0,1) -> 305.17 | F38: =_xlfn.XLOOKUP(A:A,TD!A:A,TD!EC:EC,"",0,1) -> 6.4444444 | G38: =INT(F38) -> 6 | H38: =D38*$G$5 -> 1225.86 | I38: =E38*$G$5 -> 915.51 | J38: 29012 | K38: =_xlfn.XLOOKUP(J:J,'[3]FILTROS 2'!$A:$A,'[3]FILTROS 2'!$E:$E,"",0,1) -> PASTA RELLENADORA | O38: =_xlfn.XLOOKUP(A:A,[4]TD90D!$A:$A,[4]TD90D!$CW:$CW,"",0,1) -> 11 | P38: =_xlfn.XLOOKUP(A:A,[4]TD90D!$A:$A,[4]TD90D!$CX:$CX,"",0,1) -> 3 | Q38: =_xlfn.XLOOKUP(A:A,[4]TD90D!$A:$A,[4]TD90D!$DA:$DA,"",0,1) -> 0 | R38: =P38/C38 -> 0.33333333 | S38: =_xlfn.XLOOKUP(A:A,'[4]TD90D PZAS'!$A:$A,'[4]TD90D PZAS'!$CW:$CW,"",0,1) -> 100 | T38: =_xlfn.XLOOKUP(A:A,'[4]TD90D PZAS'!$A:$A,'[4]TD90D PZAS'!$CX:$CX,"",0,1) -> 3 | U38: =_xlfn.XLOOKUP(A:A,'[4]TD90D PZAS'!$A:$A,'[4]TD90D PZAS'!$DA:$DA,"",0,1) -> 0
A39: BAG-10886 | B39: =_xlfn.XLOOKUP(A:A,[1]Hoja1!$C:$C,[1]Hoja1!$D:$D,"",0,1) -> BARNIZ GLOSI ALQUI CAOBA | C39: 9 | D39: =_xlfn.XLOOKUP(A:A,[2]Hoja1!$C:$C,[2]Hoja1!$H:$H,"",0,1) -> 68.97 | E39: =_xlfn.XLOOKUP(A:A,[1]Hoja1!$C:$C,[1]Hoja1!$H:$H,"",0,1) -> 52.59 | F39: =_xlfn.XLOOKUP(A:A,TD!A:A,TD!EC:EC,"",0,1) -> 3.3333333 | G39: =INT(F39) -> 3 | H39: =D39*$G$5 -> 206.91 | I39: =E39*$G$5 -> 157.77 | J39: BAG-10886 | K39: =_xlfn.XLOOKUP(J:J,'[3]FILTROS 2'!$A:$A,'[3]FILTROS 2'!$E:$E,"",0,1) -> BARNIZ ALQUIDALICO GLOSI 3-1 | O39: =_xlfn.XLOOKUP(A:A,[4]TD90D!$A:$A,[4]TD90D!$CW:$CW,"",0,1) -> 4 | P39: =_xlfn.XLOOKUP(A:A,[4]TD90D!$A:$A,[4]TD90D!$CX:$CX,"",0,1) -> 1 | Q39: =_xlfn.XLOOKUP(A:A,[4]TD90D!$A:$A,[4]TD90D!$DA:$DA,"",0,1) -> 0 | R39: =P39/C39 -> 0.11111111 | S39: =_xlfn.XLOOKUP(A:A,'[4]TD90D PZAS'!$A:$A,'[4]TD90D PZAS'!$CW:$CW,"",0,1) -> 6 | T39: =_xlfn.XLOOKUP(A:A,'[4]TD90D PZAS'!$A:$A,'[4]TD90D PZAS'!$CX:$CX,"",0,1) -> 1 | U39: =_xlfn.XLOOKUP(A:A,'[4]TD90D PZAS'!$A:$A,'[4]TD90D PZAS'!$DA:$DA,"",0,1) -> 0
A40: 2393 | B40: =_xlfn.XLOOKUP(A:A,[1]Hoja1!$C:$C,[1]Hoja1!$D:$D,"",0,1) -> AEROSOL GRIS CLARO | C40: 8 | D40: =_xlfn.XLOOKUP(A:A,[2]Hoja1!$C:$C,[2]Hoja1!$H:$H,"",0,1) -> 55.17 | E40: =_xlfn.XLOOKUP(A:A,[1]Hoja1!$C:$C,[1]Hoja1!$H:$H,"",0,1) -> 41.38 | F40: =_xlfn.XLOOKUP(A:A,TD!A:A,TD!EC:EC,"",0,1) -> 5.25 | G40: =INT(F40) -> 5 | H40: =D40*$G$5 -> 165.51 | I40: =E40*$G$5 -> 124.14 | J40: 2393 | K40: =_xlfn.XLOOKUP(J:J,'[3]FILTROS 2'!$A:$A,'[3]FILTROS 2'!$E:$E,"",0,1) -> AEROSOLES PRISA | O40: =_xlfn.XLOOKUP(A:A,[4]TD90D!$A:$A,[4]TD90D!$CW:$CW,"",0,1) -> 6 | P40: =_xlfn.XLOOKUP(A:A,[4]TD90D!$A:$A,[4]TD90D!$CX:$CX,"",0,1) -> 3 | Q40: =_xlfn.XLOOKUP(A:A,[4]TD90D!$A:$A,[4]TD90D!$DA:$DA,"",0,1) -> 0 | R40: =P40/C40 -> 0.375 | S40: =_xlfn.XLOOKUP(A:A,'[4]TD90D PZAS'!$A:$A,'[4]TD90D PZAS'!$CW:$CW,"",0,1) -> 36 | T40: =_xlfn.XLOOKUP(A:A,'[4]TD90D PZAS'!$A:$A,'[4]TD90D PZAS'!$CX:$CX,"",0,1) -> 2 | U40: =_xlfn.XLOOKUP(A:A,'[4]TD90D PZAS'!$A:$A,'[4]TD90D PZAS'!$DA:$DA,"",0,1) -> 0
A41: VG-30013 | B41: =_xlfn.XLOOKUP(A:A,[1]Hoja1!$C:$C,[1]Hoja1!$D:$D,"",0,1) -> VINILICA GLOSI BLANCO BASIC | C41: 8 | D41: =_xlfn.XLOOKUP(A:A,[2]Hoja1!$C:$C,[2]Hoja1!$H:$H,"",0,1) -> 219.83 | E41: =_xlfn.XLOOKUP(A:A,[1]Hoja1!$C:$C,[1]Hoja1!$H:$H,"",0,1) -> 163.79 | F41: =_xlfn.XLOOKUP(A:A,TD!A:A,TD!EC:EC,"",0,1) -> 3.5 | G41: =INT(F41) -> 3 | H41: =D41*$G$5 -> 659.49 | I41: =E41*$G$5 -> 491.37 | J41: VG-30013 | K41: =_xlfn.XLOOKUP(J:J,'[3]FILTROS 2'!$A:$A,'[3]FILTROS 2'!$E:$E,"",0,1) -> VINILICA - GLOSI BASIC | O41: =_xlfn.XLOOKUP(A:A,[4]TD90D!$A:$A,[4]TD90D!$CW:$CW,"",0,1) -> 9 | P41: =_xlfn.XLOOKUP(A:A,[4]TD90D!$A:$A,[4]TD90D!$CX:$CX,"",0,1) -> 4 | Q41: =_xlfn.XLOOKUP(A:A,[4]TD90D!$A:$A,[4]TD90D!$DA:$DA,"",0,1) -> 0 | R41: =P41/C41 -> 0.5 | S41: =_xlfn.XLOOKUP(A:A,'[4]TD90D PZAS'!$A:$A,'[4]TD90D PZAS'!$CW:$CW,"",0,1) -> 38 | T41: =_xlfn.XLOOKUP(A:A,'[4]TD90D PZAS'!$A:$A,'[4]TD90D PZAS'!$CX:$CX,"",0,1) -> 4 | U41: =_xlfn.XLOOKUP(A:A,'[4]TD90D PZAS'!$A:$A,'[4]TD90D PZAS'!$DA:$DA,"",0,1) -> 0
...

Sheet SUGERIDO FINAL
A1: SKU | B1: PRODUCTO | C1: MARCA | D1: PROPUESTA
A2: 28984 | B2: =_xlfn.XLOOKUP(A:A,[1]Hoja1!$C:$C,[1]Hoja1!$D:$D,"",0,1) -> BRILLON NEGRO | C2: ESMALTE - BRILLON | D2: ='POR PRODUCTO MAS COM'!L7 -> 4
A3: 28004 | B3: =_xlfn.XLOOKUP(A:A,[1]Hoja1!$C:$C,[1]Hoja1!$D:$D,"",0,1) -> ESMALTE BRILLON BLANCO | C3: ESMALTE - BRILLON | D3: ='POR PRODUCTO MAS COM'!L8 -> 4
A4: 28005 | B4: =_xlfn.XLOOKUP(A:A,[1]Hoja1!$C:$C,[1]Hoja1!$D:$D,"",0,1) -> BRILLON BLANCO | C4: ESMALTE - BRILLON | D4: ='POR PRODUCTO MAS COM'!L9 -> 3
A5: 28985 | B5: =_xlfn.XLOOKUP(A:A,[1]Hoja1!$C:$C,[1]Hoja1!$D:$D,"",0,1) -> BRILLON NEGRO | C5: ESMALTE - BRILLON | D5: ='POR PRODUCTO MAS COM'!L10 -> 4
A6: 28986 | B6: =_xlfn.XLOOKUP(A:A,[1]Hoja1!$C:$C,[1]Hoja1!$D:$D,"",0,1) -> BRILLON NEGRO | C6: ESMALTE - BRILLON | D6: ='POR PRODUCTO MAS COM'!L11 -> 4
A7: 28006 | B7: =_xlfn.XLOOKUP(A:A,[1]Hoja1!$C:$C,[1]Hoja1!$D:$D,"",0,1) -> BRILLON BLANCO | C7: ESMALTE - BRILLON | D7: ='POR PRODUCTO MAS COM'!L12 -> 4
A8: 2399 | B8: =_xlfn.XLOOKUP(A:A,[1]Hoja1!$C:$C,[1]Hoja1!$D:$D,"",0,1) -> AEROSOL NEGRO BRILLANTE | C8: AEROSOLES PRISA | D8: ='POR PRODUCTO MAS COM'!L13 -> 6
A9: 2300 | B9: =_xlfn.XLOOKUP(A:A,[1]Hoja1!$C:$C,[1]Hoja1!$D:$D,"",0,1) -> AEROSOL BLANCO BRILLANTE | C9: AEROSOLES PRISA | D9: ='POR PRODUCTO MAS COM'!L14 -> 6
A10: 29014 | B10: =_xlfn.XLOOKUP(A:A,[1]Hoja1!$C:$C,[1]Hoja1!$D:$D,"",0,1) -> RELLENADOR AUTOMOTRIZ C/CATAL. ROJO | C10: PASTA RELLENADORA | D10: ='POR PRODUCTO MAS COM'!L15 -> 3
A11: 79234 | B11: =_xlfn.XLOOKUP(A:A,[1]Hoja1!$C:$C,[1]Hoja1!$D:$D,"",0,1) -> SIAMIL ECONOMICO MI FL 20 KG | C11: SIAMIL | D11: ='POR PRODUCTO MAS COM'!L16 -> 4
A12: 2398 | B12: =_xlfn.XLOOKUP(A:A,[1]Hoja1!$C:$C,[1]Hoja1!$D:$D,"",0,1) -> AEROSOL NEGRO MATE | C12: AEROSOLES PRISA | D12: ='POR PRODUCTO MAS COM'!L18 -> 5
A13: 2390 | B13: =_xlfn.XLOOKUP(A:A,[1]Hoja1!$C:$C,[1]Hoja1!$D:$D,"",0,1) -> AEROSOL ALUMINIO | C13: AEROSOLES PRISA | D13: ='POR PRODUCTO MAS COM'!L20 -> 3
A14: VG-50013 | B14: =_xlfn.XLOOKUP(A:A,[1]Hoja1!$C:$C,[1]Hoja1!$D:$D,"",0,1) -> VINILICA GLOSI BLANCO ULTRA | C14: VINILICA - GLOSI 3 AÑOS | D14: ='POR PRODUCTO MAS COM'!L22 -> 8
